Workbook
Name P_Regio: Parameters!$C$5
Name P_RJ: Parameters!$C$6
Name P_Peildatum: Parameters!$C$7
Name P_PeilMaand: Parameters!$C$8
Name P_PeilTxt: Parameters!$C$9
Name P_UploadVJ: Parameters!$C$10
Name P_UploadVersie: Parameters!$C$11
Name P_VJ: Parameters!$C$12
Name P_Eenheid: Parameters!$C$13
Name P_Factor: Parameters!$C$14
Name P_Demo: Parameters!$C$15
Name P_ImportID: Parameters!$C$16
Name P_BronZ: Parameters!$C$17
Name P_BronE: Parameters!$C$18
Name P_Importdatum: Parameters!$C$19
Name P_RegelsZ: Parameters!$C$20
Name P_RegelsE: Parameters!$C$21
Name P_StatusVastleg: Parameters!$C$22
Name P_ToelCorrectie: Parameters!$C$23
Name P_Tol: Parameters!$C$24
Name V_List: Parameters!$B$28:$B$32
Name V_Maand: Parameters!$D$28:$D$32
Name L_TypeList: Parameters!$C$34:$E$34
Name L_EenheidList: Parameters!$C$35:$E$35
Name L_JaNee: Parameters!$C$36:$D$36
Name L_StatusList: Parameters!$C$37:$D$37
Name L_AanvStatus: Parameters!$C$38:$F$38
Name L_Rubrieken: Parameters!$C$39:$I$39
Name L_Soort: Parameters!$C$40:$D$40
Name L_Niveau: Parameters!$C$41:$D$41
Name L_Doeljaar: Vastlegging!$I$6:$I$5005
Name L_Projecten: Parameters!$C$44:$C$144
Name L_ProjectenDet: Parameters!$C$45:$C$144
Name YM_Intern: Veldwoordenboek!$B$6:$B$14
Name YM_Header: Veldwoordenboek!$C$6:$C$14
Name Map_WBS: Mapping!$A$5:$A$104
Name Map_Projdef: Mapping!$B$5:$B$104
Name Map_Naam: Mapping!$C$5:$C$104
Name Map_Aantal: Mapping!$D$5:$D$104
Name Map_Aandeel: Mapping!$E$5:$E$104
Name Map_Type: Mapping!$F$5:$F$104
Name Map_Meetellen: Mapping!$G$5:$G$104
Name Map_Segment: Mapping!$H$5:$H$104
Name L_ImportID: Vastlegging!$A$6:$A$5005
Name L_Bronbestand: Vastlegging!$B$6:$B$5005
Name L_Importdatum: Vastlegging!$C$6:$C$5005
Name L_Status: Vastlegging!$D$6:$D$5005
Name L_Versiejaar: Vastlegging!$E$6:$E$5005
Name L_Versie: Vastlegging!$F$6:$F$5005
Name L_Revisie: Vastlegging!$G$6:$G$5005
Name L_Peildatum: Vastlegging!$H$6:$H$5005
Name L_WBS: Vastlegging!$J$6:$J$5005
Name L_Projectdefinitie: Vastlegging!$K$6:$K$5005
Name L_Projectnaam: Vastlegging!$L$6:$L$5005
Name L_Type: Vastlegging!$M$6:$M$5005
Name L_IFRS: Vastlegging!$N$6:$N$5005
Name L_Kengetal: Vastlegging!$O$6:$O$5005
Name L_Waarde: Vastlegging!$P$6:$P$5005
Name L_Eenheid: Vastlegging!$Q$6:$Q$5005
Name L_Toelichting: Vastlegging!$R$6:$R$5005

Sheet Start
B1: RDFO-prototype — fictieve demodata
B2: Werkend prototype op uitsluitend fictieve data. Demo-aannames zijn geen vastgestelde SAP-definities.
B4: Status | C4: =IF(Controle!$D$4>0,"✖ "&Controle!$D$4&" FOUT(en) — zie Controle",IF(Controle!$D$5>0,"▲ geen fouten, "&Controle!$D$5&" waarschuwing(en)","✔ geen fouten of waarschuwingen")) -> ✔ geen fouten of waarschuwingen
C5: ="Upload: "&P_UploadVersie&" "&P_UploadVJ&" · peildatum "&P_PeilTxt&" · Import-ID "&P_ImportID&" · rapportage: doeljaar "&Sel_Doeljaar&", "&Sel_Label -> Upload: Q3 2026 · peildatum 30-09-2026 · Import-ID IMP-2026-Q3-01 · rapportage: doeljaar 2026, Q3 2026 (vastgesteld)
E7: Legenda
B8: Rapportage | E8: Invoercel (blauw cijfer, lichtgeel)
B9: Dashboard | C9: Regiodashboard: filters (doeljaar, versie, type, project), KPI-tegels, prognoseverloop, mutaties, doorkijk. | E9: Geselecteerde versie (geel vlak)
B10: RDFO | C10: Volledige RDFO-opbouw: Budget, Q1–Q4 vastgelegd, upload-concept, realisatie YTD, to go, delta’s. | E10: Realisatie / actual (groen, cursief)
B11: Projecten | C11: Per project: versies, realisatie, to go, BOR, marge, verschillen + toelichting. | E11: Subtotaal onvolledig (bevat n.b.)
B12: Projectdetail | C12: Eén project: kerngegevens, versieverloop, planning omzet/BOR, woningverkopen. | E12: KPI-tegel / totaal
B13: Woningen | C13: Verkopen per maand/kwartaal, jaarverwachting per versie, koperstype, segment, projectmatrix. | E13: Bronkop
B14: Controle | C14: Alle controles met status en uitzonderingslijsten.
E15: n.b. = niet beschikbaar · n.v.t. = niet van toepassing
B16: Invoer | E16: Bedragen bron: EUR, volle precisie
B17: Parameters | C17: Rapportagejaar, peildatum, uploadversie, eenheid, Import-ID, status bij vastleggen. | E17: Omzet/winst positief, verlies negatief
B18: Invoer_Aanvullend | C18: Posten die niet uit de bronnen komen (taakstelling, eliminaties, AK-dekking, fees …).
B19: Invoer_Toelichting | C19: Toelichtingen op verschillen per project en versie.
B20: Invoer_Koperstype | C20: Optionele koperstype-verdeling voor toekomstige verkopen.
B21: Mapping | C21: Projectmapping WBS → projectdefinitie, type, segment, woningen meetellen.
B23: Versiebeheer
B24: Vastlegging | C24: Onveranderlijk versiegrootboek (alleen toevoegen).
B25: Vastleggen | C25: Concept van de huidige upload in grootboekformaat — HANDMATIG kopiëren/plakken als waarden.
B26: Importlog | C26: Audittrail per import/vastlegging.
B28: Bron en verwerking (niet wijzigen)
B29: SRC_ZPMW03 | C29: Ongewijzigde export ZPMW03 — hier plakken.
B30: SRC_Woningetalage | C30: Ongewijzigde export Woningetalage — hier plakken.
B31: STG_ZPMW03 | C31: Staging: velden gezocht op kolomnaam, tekenomzetting, regelcontroles.
B32: STG_Woningetalage | C32: Staging: dubbele headers op positie, jaarheaders via mapping, regelcontroles.
B33: VERW_Project | C33: Eén regel per gemapt WBS; elke bron eerst per WBS geaggregeerd.
B34: CALC_Versies | C34: Totalen per versie (regio en gefilterd), geselecteerde en vorige versie.
B36: Documentatie
B37: Handleiding | C37: Bronvervanging, verversen, kwartaalvastlegging, correcties.
B38: Rapportagemapping | C38: Elke rapportageregel → bron / berekening / aanvullende invoer + open definities.
B39: Productievragen | C39: Openstaande vragen vóór productie.
B40: Veldwoordenboek | C40: Interne veldnamen, aliassen, dubbele headers, jaarheader-mapping.
B41: Testresultaten | C41: Uitgevoerde scenario-tests (nieuwe upload, dubbele import, correctie, weging, verlies).
B43: Ontwerpkeuze
B44: Keuze | C44: Excel met gestructureerde lagen en formule-staging op kolomnaam; géén Power Query, géén macro's.
B45: Waarom geen Power Query (nu) | C45: De bronnen worden per ronde handmatig vervangen en zijn klein (tientallen tot honderden regels). Een plak-tabblad met staging op kolomnaam geeft hetzelfde voordeel als Power Query (kolomvolgorde mag wijzigen, aliassen, dubbele headers op positie) maar werkt in elke Excelversie, rekent direct mee, is cel-voor-cel controleerbaar en kon in dit prototype automatisch getest worden. Power Query-queries kunnen in deze bouwomgeving niet worden uitgevoerd of getest; een ongeteste query opleveren past niet bij 'beloof niets dat niet werkt'.
B46: Wanneer wél Power Query | C46: Als bronnen uit een vaste map/SharePoint komen of groter worden dan ~500 regels. De staginglaag (STG_*) is dan 1-op-1 te vervangen door een query die dezelfde interne veldnamen (Veldwoordenboek) oplevert; rapportage en versiebeheer blijven ongewijzigd.
...

Sheet Dashboard
B1: ="Regiodashboard "&P_Regio&" — doeljaar "&Sel_Doeljaar&" · versie "&Sel_Label -> Regiodashboard Demo Regio — doeljaar 2026 · versie Q3 2026 (vastgesteld)
B2: ="Bedragen in EUR mln (bron: EUR, volledige precisie) · upload peildatum "&P_PeilTxt&" · filter: "&Sel_FiltLabel -> Bedragen in EUR mln (bron: EUR, volledige precisie) · upload peildatum 30-09-2026 · filter: geen filter
B4: Doeljaar | E4: Versie | H4: Opstal / deelneming | K4: Project | P4: Controlestatus
B5: 2026 | E5: Q3 | H5: Alle | K5: Alle | P5: =IF(Controle!$D$4>0,"✖ "&Controle!$D$4&" fout(en)",IF(Controle!$D$5>0,"▲ "&Controle!$D$5&" waarschuwing(en)","✔ geen fouten")) -> ✔ geen fouten
B7: ="Omzet FY "&Sel_Doeljaar&" · "&Sel_Versie -> Omzet FY 2026 · Q3 | E7: ="BOR FY "&Sel_Doeljaar&" · "&Sel_Versie -> BOR FY 2026 · Q3 | H7: Realisatie YTD (zelfde peildatum) | K7: Omzet to go (FY − realisatie) | N7: ="Woningverkopen "&Sel_Doeljaar&" · "&Sel_Versie -> Woningverkopen 2026 · Q3 | Q7: Etalage (upload, onverkocht)
B8: =IF(ISNUMBER(CALC_Versies!$S$11),CALC_Versies!$S$11/1000000,"n.b.") -> 114.0968 | E8: =IF(ISNUMBER(CALC_Versies!$T$11),CALC_Versies!$T$11/1000000,"n.b.") -> 10.477198 | H8: =IF(ISNUMBER(CALC_Versies!$U$11),CALC_Versies!$U$11/1000000,CALC_Versies!$U$11) -> 74.16292 | K8: =IF(CALC_Versies!$U$11="n.v.t.",IF(ISNUMBER(CALC_Versies!$S$11),CALC_Versies!$S$11/1000000,"n.b."),IF(AND(ISNUMBER(CALC_Versies!$S$11),ISNUMBER(CALC_Versies!$U$11)),(CALC_Versies!$S$11-CALC_Versies!$U$11)/1000000,"n.b.")) -> 39.93388 | N8: =CALC_Versies!$W$11 -> 360 | Q8: =SUMIFS(V_W_Etalage,V_Meetellen,"Ja",V_Type,Sel_TypeCrit,V_WBS,Sel_WBS) -> 902
B9: ="Δ budget: "&IF(AND(ISNUMBER(CALC_Versies!$S$11),ISNUMBER(CALC_Versies!$S$5)),FIXED((CALC_Versies!$S$11-CALC_Versies!$S$5)/1000000,1)&" mln","n.b.") -> Δ budget: -4.4 mln | E9: ="BOR %: "&IF(AND(ISNUMBER(CALC_Versies!$T$11),ISNUMBER(CALC_Versies!$S$11)),IF(CALC_Versies!$S$11<>0,FIXED(CALC_Versies!$T$11/CALC_Versies!$S$11*100,1)&"%","n.b."),"n.b.") -> BOR %: 9.2% | H9: =IF(AND(ISNUMBER(CALC_Versies!$U$11),ISNUMBER(CALC_Versies!$S$11)),IF(CALC_Versies!$S$11<>0,FIXED(CALC_Versies!$U$11/CALC_Versies!$S$11*100,0)&"% van FY-prognose","n.b."),"voortgang n.b.") -> 65% van FY-prognose | K9: ="BOR to go: "&IF(CALC_Versies!$V$11="n.v.t.",IF(ISNUMBER(CALC_Versies!$T$11),FIXED(CALC_Versies!$T$11/1000000,1),"n.b."),IF(AND(ISNUMBER(CALC_Versies!$T$11),ISNUMBER(CALC_Versies!$V$11)),FIXED((CALC_Versies!$T$11-CALC_Versies!$V$11)/1000000,1),"n.b."))&" mln" -> BOR to go: 3.7 mln | N9: ="actual YTD: "&CALC_Versies!$X$11 -> actual YTD: 193 | Q9: ="verkocht: "&IF(SUMIFS(V_W_Aantal,V_Meetellen,"Ja",V_Type,Sel_TypeCrit,V_WBS,Sel_WBS)=0,"n.b.",FIXED(SUMIFS(V_W_Cum_T,V_Meetellen,"Ja",V_Type,Sel_TypeCrit,V_WBS,Sel_WBS)/SUMIFS(V_W_Aantal,V_Meetellen,"Ja",V_Type,Sel_TypeCrit,V_WBS,Sel_WBS)*100,0)&"%") -> verkocht: 22%
B10: ="Δ "&IF(Sel_Prev="","vorige",Sel_Prev)&": "&IF(AND(ISNUMBER(CALC_Versies!$S$11),ISNUMBER(CALC_Versies!$S$12)),FIXED((CALC_Versies!$S$11-CALC_Versies!$S$12)/1000000,1)&" mln","n.b.") -> Δ Q2: 1.3 mln | E10: ="Δ budget: "&IF(AND(ISNUMBER(CALC_Versies!$T$11),ISNUMBER(CALC_Versies!$T$5)),FIXED((CALC_Versies!$T$11-CALC_Versies!$T$5)/1000000,1)&" mln","n.b.") -> Δ budget: -0.3 mln | H10: =IF(AND(ISNUMBER(CALC_Versies!$U$11),ISNUMBER(CALC_Versies!$S$11)),IF(CALC_Versies!$S$11<>0,CALC_Versies!$U$11/CALC_Versies!$S$11,0),0) -> 0.65 | K10: ="nooit oude prognose − nieuwe actual" -> nooit oude prognose − nieuwe actual | N10: ="budget: "&CALC_Versies!$W$5 -> budget: 372 | Q10: ="verliesprojecten (upload): "&SUMIFS(V_Verlies,V_Type,Sel_TypeCrit,V_WBS,Sel_WBS) -> verliesprojecten (upload): 2
B12: ="Jaarprognoseverloop "&Sel_Doeljaar&": FY-omzet en BOR per vastgelegde versie (EUR mln)" -> Jaarprognoseverloop 2026: FY-omzet en BOR per vastgelegde versie (EUR mln) | K12: ="Realisatie vs resterende prognose — top 10 projecten, "&Sel_Label&" (EUR mln)" -> Realisatie vs resterende prognose — top 10 projecten, Q3 2026 (vastgesteld) (EUR mln)
B30: ="Grootste projectmutaties "&Sel_Versie&" vs "&IF(Sel_Prev="","–",Sel_Prev)&" (Δ FY-omzet, EUR mln)" -> Grootste projectmutaties Q3 vs Q2 (Δ FY-omzet, EUR mln) | K30: ="Meerjarendoorkijk upload "&P_PeilTxt&" (EUR mln)" -> Meerjarendoorkijk upload 30-09-2026 (EUR mln)
B47: Kolommen met '(n.b.)' in het label hebben geen vastgelegde versie: de staaf ontbreekt bewust (niet nul). Realisatie (donkerblauw) en resterende prognose (geel) zijn gescheiden.
B48: Grafiekdata (gekoppeld aan CALC_Versies / Projecten / VERW_Project — niet overschrijven)
B49: A. Jaarprognoseverloop (EUR mln) | H49: B. Top 10 projecten: realisatie vs to go (EUR mln, geselecteerde versie) | N49: C. Grootste mutaties vs vorige versie (EUR mln)
B50: Versie | C50: Label | D50: Omzet FY | E50: BOR FY | F50: BOR % | H50: # | I50: Project | J50: Realisatie YTD | K50: To go | L50: FY | N50: # | O50: Project | P50: Δ omzet FY
B51: Budget | C51: =B51&IF(ISNUMBER(CALC_Versies!$S$5),""," (n.b.)") -> Budget | D51: =IF(ISNUMBER(CALC_Versies!$S$5),CALC_Versies!$S$5/1000000,0) -> 118.52544 | E51: =IF(ISNUMBER(CALC_Versies!$T$5),CALC_Versies!$T$5/1000000,0) -> 10.769875 | F51: =IF(AND(ISNUMBER(CALC_Versies!$S$5),ISNUMBER(CALC_Versies!$T$5)),IF(CALC_Versies!$S$5<>0,CALC_Versies!$T$5/CALC_Versies!$S$5,"n.b."),"n.b.") -> 0.090865514 | H51: 1 | I51: =IF($Q51=0,"",INDEX(Projecten!$B$10:$B$109,$Q51)) -> Duinwaard, Duinrand | J51: =IF($Q51=0,0,IF(ISNUMBER(INDEX(Projecten!$L$10:$L$109,$Q51)),INDEX(Projecten!$L$10:$L$109,$Q51)*P_Factor/1000000,0)) -> 10.8108 | K51: =IF($Q51=0,0,IF(ISNUMBER(INDEX(Projecten!$M$10:$M$109,$Q51)),INDEX(Projecten!$M$10:$M$109,$Q51)*P_Factor/1000000,0)) -> 5.8212 | L51: =IF($Q51=0,0,INDEX(Projecten!$K$10:$K$109,$Q51)*P_Factor/1000000) -> 16.632 | N51: 1 | O51: =IF($R51=0,"",INDEX(Projecten!$B$10:$B$109,$R51)) -> Duinwaard, Duinrand | P51: =IF($R51=0,0,INDEX(Projecten!$Q$10:$Q$109,$R51)*P_Factor/1000000) -> 0.49896 | Q51: =IFERROR(MATCH(LARGE(Projecten!$U$10:$U$109,1),Projecten!$U$10:$U$109,0),0) -> 9 | R51: =IFERROR(MATCH(LARGE(Projecten!$V$10:$V$109,1),Projecten!$V$10:$V$109,0),0) -> 9
B52: Q1 | C52: =B52&IF(ISNUMBER(CALC_Versies!$S$6),""," (n.b.)") -> Q1 | D52: =IF(ISNUMBER(CALC_Versies!$S$6),CALC_Versies!$S$6/1000000,0) -> 116.75398 | E52: =IF(ISNUMBER(CALC_Versies!$T$6),CALC_Versies!$T$6/1000000,0) -> 10.652804 | F52: =IF(AND(ISNUMBER(CALC_Versies!$S$6),ISNUMBER(CALC_Versies!$T$6)),IF(CALC_Versies!$S$6<>0,CALC_Versies!$T$6/CALC_Versies!$S$6,"n.b."),"n.b.") -> 0.091241462 | H52: 2 | I52: =IF($Q52=0,"",INDEX(Projecten!$B$10:$B$109,$Q52)) -> Meerhovenstad, Hofstaete | J52: =IF($Q52=0,0,IF(ISNUMBER(INDEX(Projecten!$L$10:$L$109,$Q52)),INDEX(Projecten!$L$10:$L$109,$Q52)*P_Factor/1000000,0)) -> 9.4848 | K52: =IF($Q52=0,0,IF(ISNUMBER(INDEX(Projecten!$M$10:$M$109,$Q52)),INDEX(Projecten!$M$10:$M$109,$Q52)*P_Factor/1000000,0)) -> 5.1072 | L52: =IF($Q52=0,0,INDEX(Projecten!$K$10:$K$109,$Q52)*P_Factor/1000000) -> 14.592 | N52: 2 | O52: =IF($R52=0,"",INDEX(Projecten!$B$10:$B$109,$R52)) -> Meerhovenstad, Hofstaete | P52: =IF($R52=0,0,INDEX(Projecten!$Q$10:$Q$109,$R52)*P_Factor/1000000) -> 0.43776 | Q52: =IFERROR(MATCH(LARGE(Projecten!$U$10:$U$109,2),Projecten!$U$10:$U$109,0),0) -> 11 | R52: =IFERROR(MATCH(LARGE(Projecten!$V$10:$V$109,2),Projecten!$V$10:$V$109,0),0) -> 11
B53: Q2 | C53: =B53&IF(ISNUMBER(CALC_Versies!$S$7),""," (n.b.)") -> Q2 | D53: =IF(ISNUMBER(CALC_Versies!$S$7),CALC_Versies!$S$7/1000000,0) -> 112.76821 | E53: =IF(ISNUMBER(CALC_Versies!$T$7),CALC_Versies!$T$7/1000000,0) -> 10.389395 | F53: =IF(AND(ISNUMBER(CALC_Versies!$S$7),ISNUMBER(CALC_Versies!$T$7)),IF(CALC_Versies!$S$7<>0,CALC_Versies!$T$7/CALC_Versies!$S$7,"n.b."),"n.b.") -> 0.092130531 | H53: 3 | I53: =IF($Q53=0,"",INDEX(Projecten!$B$10:$B$109,$Q53)) -> Veldendam, Spoorpark | J53: =IF($Q53=0,0,IF(ISNUMBER(INDEX(Projecten!$L$10:$L$109,$Q53)),INDEX(Projecten!$L$10:$L$109,$Q53)*P_Factor/1000000,0)) -> 7.644 | K53: =IF($Q53=0,0,IF(ISNUMBER(INDEX(Projecten!$M$10:$M$109,$Q53)),INDEX(Projecten!$M$10:$M$109,$Q53)*P_Factor/1000000,0)) -> 4.116 | L53: =IF($Q53=0,0,INDEX(Projecten!$K$10:$K$109,$Q53)*P_Factor/1000000) -> 11.76 | N53: 3 | O53: =IF($R53=0,"",INDEX(Projecten!$B$10:$B$109,$R53)) -> Veldendam, Spoorpark | P53: =IF($R53=0,0,INDEX(Projecten!$Q$10:$Q$109,$R53)*P_Factor/1000000) -> 0.3528 | Q53: =IFERROR(MATCH(LARGE(Projecten!$U$10:$U$109,3),Projecten!$U$10:$U$109,0),0) -> 17 | R53: =IFERROR(MATCH(LARGE(Projecten!$V$10:$V$109,3),Projecten!$V$10:$V$109,0),0) -> 17
B54: Q3 | C54: =B54&IF(ISNUMBER(CALC_Versies!$S$8),""," (n.b.)") -> Q3 | D54: =IF(ISNUMBER(CALC_Versies!$S$8),CALC_Versies!$S$8/1000000,0) -> 114.0968 | E54: =IF(ISNUMBER(CALC_Versies!$T$8),CALC_Versies!$T$8/1000000,0) -> 10.477198 | F54: =IF(AND(ISNUMBER(CALC_Versies!$S$8),ISNUMBER(CALC_Versies!$T$8)),IF(CALC_Versies!$S$8<>0,CALC_Versies!$T$8/CALC_Versies!$S$8,"n.b."),"n.b.") -> 0.091827273 | H54: 4 | I54: =IF($Q54=0,"",INDEX(Projecten!$B$10:$B$109,$Q54)) -> Rietdam, Rietoevers | J54: =IF($Q54=0,0,IF(ISNUMBER(INDEX(Projecten!$L$10:$L$109,$Q54)),INDEX(Projecten!$L$10:$L$109,$Q54)*P_Factor/1000000,0)) -> 5.70024 | K54: =IF($Q54=0,0,IF(ISNUMBER(INDEX(Projecten!$M$10:$M$109,$Q54)),INDEX(Projecten!$M$10:$M$109,$Q54)*P_Factor/1000000,0)) -> 3.06936 | L54: =IF($Q54=0,0,INDEX(Projecten!$K$10:$K$109,$Q54)*P_Factor/1000000) -> 8.7696 | N54: 4 | O54: =IF($R54=0,"",INDEX(Projecten!$B$10:$B$109,$R54)) -> Rietdam, Rietoevers | P54: =IF($R54=0,0,INDEX(Projecten!$Q$10:$Q$109,$R54)*P_Factor/1000000) -> -0.263088 | Q54: =IFERROR(MATCH(LARGE(Projecten!$U$10:$U$109,4),Projecten!$U$10:$U$109,0),0) -> 14 | R54: =IFERROR(MATCH(LARGE(Projecten!$V$10:$V$109,4),Projecten!$V$10:$V$109,0),0) -> 14
B55: Q4 | C55: =B55&IF(ISNUMBER(CALC_Versies!$S$9),""," (n.b.)") -> Q4 (n.b.) | D55: =IF(ISNUMBER(CALC_Versies!$S$9),CALC_Versies!$S$9/1000000,0) -> 0 | E55: =IF(ISNUMBER(CALC_Versies!$T$9),CALC_Versies!$T$9/1000000,0) -> 0 | F55: =IF(AND(ISNUMBER(CALC_Versies!$S$9),ISNUMBER(CALC_Versies!$T$9)),IF(CALC_Versies!$S$9<>0,CALC_Versies!$T$9/CALC_Versies!$S$9,"n.b."),"n.b.") -> n.b. | H55: 5 | I55: =IF($Q55=0,"",INDEX(Projecten!$B$10:$B$109,$Q55)) -> Zilverdam, Kadezicht | J55: =IF($Q55=0,0,IF(ISNUMBER(INDEX(Projecten!$L$10:$L$109,$Q55)),INDEX(Projecten!$L$10:$L$109,$Q55)*P_Factor/1000000,0)) -> 4.368 | K55: =IF($Q55=0,0,IF(ISNUMBER(INDEX(Projecten!$M$10:$M$109,$Q55)),INDEX(Projecten!$M$10:$M$109,$Q55)*P_Factor/1000000,0)) -> 2.352 | L55: =IF($Q55=0,0,INDEX(Projecten!$K$10:$K$109,$Q55)*P_Factor/1000000) -> 6.72 | N55: 5 | O55: =IF($R55=0,"",INDEX(Projecten!$B$10:$B$109,$R55)) -> Zilverdam, Kadezicht | P55: =IF($R55=0,0,INDEX(Projecten!$Q$10:$Q$109,$R55)*P_Factor/1000000) -> 0.2016 | Q55: =IFERROR(MATCH(LARGE(Projecten!$U$10:$U$109,5),Projecten!$U$10:$U$109,0),0) -> 5 | R55: =IFERROR(MATCH(LARGE(Projecten!$V$10:$V$109,5),Projecten!$V$10:$V$109,0),0) -> 5
B56: Upload | C56: ="Upload "&P_PeilTxt&IF(ISNUMBER(CALC_Versies!$S$10),""," (n.b.)") -> Upload 30-09-2026 | D56: =IF(ISNUMBER(CALC_Versies!$S$10),CALC_Versies!$S$10/1000000,0) -> 114.0968 | E56: =IF(ISNUMBER(CALC_Versies!$T$10),CALC_Versies!$T$10/1000000,0) -> 10.477198 | F56: =IF(AND(ISNUMBER(CALC_Versies!$S$10),ISNUMBER(CALC_Versies!$T$10)),IF(CALC_Versies!$S$10<>0,CALC_Versies!$T$10/CALC_Versies!$S$10,"n.b."),"n.b.") -> 0.091827273 | H56: 6 | I56: =IF($Q56=0,"",INDEX(Projecten!$B$10:$B$109,$Q56)) -> Boswaard, De Eiken | J56: =IF($Q56=0,0,IF(ISNUMBER(INDEX(Projecten!$L$10:$L$109,$Q56)),INDEX(Projecten!$L$10:$L$109,$Q56)*P_Factor/1000000,0)) -> 4.26816 | K56: =IF($Q56=0,0,IF(ISNUMBER(INDEX(Projecten!$M$10:$M$109,$Q56)),INDEX(Projecten!$M$10:$M$109,$Q56)*P_Factor/1000000,0)) -> 2.29824 | L56: =IF($Q56=0,0,INDEX(Projecten!$K$10:$K$109,$Q56)*P_Factor/1000000) -> 6.5664 | N56: 6 | O56: =IF($R56=0,"",INDEX(Projecten!$B$10:$B$109,$R56)) -> Boswaard, De Eiken | P56: =IF($R56=0,0,INDEX(Projecten!$Q$10:$Q$109,$R56)*P_Factor/1000000) -> -0.196992 | Q56: =IFERROR(MATCH(LARGE(Projecten!$U$10:$U$109,6),Projecten!$U$10:$U$109,0),0) -> 6 | R56: =IFERROR(MATCH(LARGE(Projecten!$V$10:$V$109,6),Projecten!$V$10:$V$109,0),0) -> 6
H57: 7 | I57: =IF($Q57=0,"",INDEX(Projecten!$B$10:$B$109,$Q57)) -> Zilverdam, Havenlicht | J57: =IF($Q57=0,0,IF(ISNUMBER(INDEX(Projecten!$L$10:$L$109,$Q57)),INDEX(Projecten!$L$10:$L$109,$Q57)*P_Factor/1000000,0)) -> 4.0131 | K57: =IF($Q57=0,0,IF(ISNUMBER(INDEX(Projecten!$M$10:$M$109,$Q57)),INDEX(Projecten!$M$10:$M$109,$Q57)*P_Factor/1000000,0)) -> 2.1609 | L57: =IF($Q57=0,0,INDEX(Projecten!$K$10:$K$109,$Q57)*P_Factor/1000000) -> 6.174 | N57: 7 | O57: =IF($R57=0,"",INDEX(Projecten!$B$10:$B$109,$R57)) -> Zilverdam, Havenlicht | P57: =IF($R57=0,0,INDEX(Projecten!$Q$10:$Q$109,$R57)*P_Factor/1000000) -> 0.18522 | Q57: =IFERROR(MATCH(LARGE(Projecten!$U$10:$U$109,7),Projecten!$U$10:$U$109,0),0) -> 19 | R57: =IFERROR(MATCH(LARGE(Projecten!$V$10:$V$109,7),Projecten!$V$10:$V$109,0),0) -> 19
H58: 8 | I58: =IF($Q58=0,"",INDEX(Projecten!$B$10:$B$109,$Q58)) -> Rietdam, Havenkwartier | J58: =IF($Q58=0,0,IF(ISNUMBER(INDEX(Projecten!$L$10:$L$109,$Q58)),INDEX(Projecten!$L$10:$L$109,$Q58)*P_Factor/1000000,0)) -> 3.952 | K58: =IF($Q58=0,0,IF(ISNUMBER(INDEX(Projecten!$M$10:$M$109,$Q58)),INDEX(Projecten!$M$10:$M$109,$Q58)*P_Factor/1000000,0)) -> 2.128 | L58: =IF($Q58=0,0,INDEX(Projecten!$K$10:$K$109,$Q58)*P_Factor/1000000) -> 6.08 | N58: 8 | O58: =IF($R58=0,"",INDEX(Projecten!$B$10:$B$109,$R58)) -> Rietdam, Havenkwartier | P58: =IF($R58=0,0,INDEX(Projecten!$Q$10:$Q$109,$R58)*P_Factor/1000000) -> 0.1824 | Q58: =IFERROR(MATCH(LARGE(Projecten!$U$10:$U$109,8),Projecten!$U$10:$U$109,0),0) -> 7 | R58: =IFERROR(MATCH(LARGE(Projecten!$V$10:$V$109,8),Projecten!$V$10:$V$109,0),0) -> 7
H59: 9 | I59: =IF($Q59=0,"",INDEX(Projecten!$B$10:$B$109,$Q59)) -> Lindehaven, Parkzoom fase 1 | J59: =IF($Q59=0,0,IF(ISNUMBER(INDEX(Projecten!$L$10:$L$109,$Q59)),INDEX(Projecten!$L$10:$L$109,$Q59)*P_Factor/1000000,0)) -> 3.63584 | K59: =IF($Q59=0,0,IF(ISNUMBER(INDEX(Projecten!$M$10:$M$109,$Q59)),INDEX(Projecten!$M$10:$M$109,$Q59)*P_Factor/1000000,0)) -> 1.95776 | L59: =IF($Q59=0,0,INDEX(Projecten!$K$10:$K$109,$Q59)*P_Factor/1000000) -> 5.5936 | Q59: =IFERROR(MATCH(LARGE(Projecten!$U$10:$U$109,9),Projecten!$U$10:$U$109,0),0) -> 1
H60: 10 | I60: =IF($Q60=0,"",INDEX(Projecten!$B$10:$B$109,$Q60)) -> Duinwaard, De Lantaarn | J60: =IF($Q60=0,0,IF(ISNUMBER(INDEX(Projecten!$L$10:$L$109,$Q60)),INDEX(Projecten!$L$10:$L$109,$Q60)*P_Factor/1000000,0)) -> 3.1616 | K60: =IF($Q60=0,0,IF(ISNUMBER(INDEX(Projecten!$M$10:$M$109,$Q60)),INDEX(Projecten!$M$10:$M$109,$Q60)*P_Factor/1000000,0)) -> 1.7024 | L60: =IF($Q60=0,0,INDEX(Projecten!$K$10:$K$109,$Q60)*P_Factor/1000000) -> 4.864 | N60: =IF(Sel_Prev="","Budget heeft geen vorige versie: geen mutaties.",IF(COUNT(Projecten!$V$10:$V$109)=0,"Geen mutaties beschikbaar (vorige versie n.b.).","")) | Q60: =IFERROR(MATCH(LARGE(Projecten!$U$10:$U$109,10),Projecten!$U$10:$U$109,0),0) -> 16
B62: D. Meerjarendoorkijk huidige upload (EUR mln, niet vastgelegd)
B63: Jaar | C63: Omzet | D63: BOR
B64: =P_RJ&" FY" -> 2026 FY | C64: =SUMIFS(V_OmzFY,V_Type,Sel_TypeCrit,V_WBS,Sel_WBS)/1000000 -> 114.0968 | D64: =SUMIFS(V_BorFY,V_Type,Sel_TypeCrit,V_WBS,Sel_WBS)/1000000 -> 10.477198
B65: =(P_RJ+1)&"" -> 2027 | C65: =SUMIFS(V_OmzFY1,V_Type,Sel_TypeCrit,V_WBS,Sel_WBS)/1000000 -> 218.82848 | D65: =SUMIFS(V_BorFY1,V_Type,Sel_TypeCrit,V_WBS,Sel_WBS)/1000000 -> 18.301141
B66: =(P_RJ+2)&"" -> 2028 | C66: =SUMIFS(V_OmzRJ2,V_Type,Sel_TypeCrit,V_WBS,Sel_WBS)/1000000 -> 117.83072 | D66: =SUMIFS(V_BorRJ2,V_Type,Sel_TypeCrit,V_WBS,Sel_WBS)/1000000 -> 9.8544607
B67: =(P_RJ+3)&"" -> 2029 | C67: =SUMIFS(V_OmzRJ3,V_Type,Sel_TypeCrit,V_WBS,Sel_WBS)/1000000 -> 0 | D67: =SUMIFS(V_BorRJ3,V_Type,Sel_TypeCrit,V_WBS,Sel_WBS)/1000000 -> 0
B68: =(P_RJ+4)&"" -> 2030 | C68: =SUMIFS(V_OmzRJ4,V_Type,Sel_TypeCrit,V_WBS,Sel_WBS)/1000000 -> 0 | D68: =SUMIFS(V_BorRJ4,V_Type,Sel_TypeCrit,V_WBS,Sel_WBS)/1000000 -> 0
B69: =(P_RJ+5)&"" -> 2031 | C69: =SUMIFS(V_OmzRJ5,V_Type,Sel_TypeCrit,V_WBS,Sel_WBS)/1000000 -> 0 | D69: =SUMIFS(V_BorRJ5,V_Type,Sel_TypeCrit,V_WBS,Sel_WBS)/1000000 -> 0
B70: =(P_RJ+6)&"" -> 2032 | C70: =SUMIFS(V_OmzRJ6,V_Type,Sel_TypeCrit,V_WBS,Sel_WBS)/1000000 -> 0 | D70: =SUMIFS(V_BorRJ6,V_Type,Sel_TypeCrit,V_WBS,Sel_WBS)/1000000 -> 0
B71: =(P_RJ+7)&"" -> 2033 | C71: =SUMIFS(V_OmzRJ7,V_Type,Sel_TypeCrit,V_WBS,Sel_WBS)/1000000 -> 0 | D71: =SUMIFS(V_BorRJ7,V_Type,Sel_TypeCrit,V_WBS,Sel_WBS)/1000000 -> 0
B72: =(P_RJ+8)&"" -> 2034 | C72: =SUMIFS(V_OmzRJ8,V_Type,Sel_TypeCrit,V_WBS,Sel_WBS)/1000000 -> 0 | D72: =SUMIFS(V_BorRJ8,V_Type,Sel_TypeCrit,V_WBS,Sel_WBS)/1000000 -> 0
B73: Onverdeeld | C73: =SUMIFS(V_OmzONV,V_Type,Sel_TypeCrit,V_WBS,Sel_WBS)/1000000 -> 0 | D73: =SUMIFS(V_BorONV,V_Type,Sel_TypeCrit,V_WBS,Sel_WBS)/1000000 -> 0

Sheet RDFO
B1: ="RDFO "&P_Regio&" — doeljaar "&Sel_Doeljaar&" · bedragen in "&P_Eenheid -> RDFO Demo Regio — doeljaar 2026 · bedragen in EUR x 1.000
B2: ="Versiejaar "&P_VJ&" · geselecteerde versie: "&Sel_Label&" · vergeleken met "&IF(Sel_Prev="","–",Sel_Prev)&" · upload peildatum "&P_PeilTxt&" · selectie wijzigen op Dashboard" -> Versiejaar 2026 · geselecteerde versie: Q3 2026 (vastgesteld) · vergeleken met Q2 · upload peildatum 30-09-2026 · selectie wijzigen op Dashboard
C5: Budget | D5: Q1 | E5: Q2 | F5: Q3 | G5: Q4 | H5: Upload | J5: Sel | O5: Vorige
B6: Rubriek | C6: ="Budget"&CHAR(10)&"FY "&Sel_Doeljaar -> Budget FY 2026 | D6: ="Q1 "&P_VJ&CHAR(10)&"FY-prognose"&IF(CALC_Versies!$F$6>0," ●","") -> Q1 2026 FY-prognose | E6: ="Q2 "&P_VJ&CHAR(10)&"FY-prognose"&IF(CALC_Versies!$F$7>0," ●","") -> Q2 2026 FY-prognose | F6: ="Q3 "&P_VJ&CHAR(10)&"FY-prognose"&IF(CALC_Versies!$F$8>0," ●","") -> Q3 2026 FY-prognose | G6: ="Q4 "&P_VJ&CHAR(10)&"FY-prognose"&IF(CALC_Versies!$F$9>0," ●","") -> Q4 2026 FY-prognose | H6: ="Upload "&P_PeilTxt&CHAR(10)&"concept" -> Upload 30-09-2026 concept | J6: ="Geselecteerd"&CHAR(10)&Sel_Versie&" FY" -> Geselecteerd Q3 FY | K6: ="Realisatie YTD"&CHAR(10)&"zelfde peildatum" -> Realisatie YTD zelfde peildatum | L6: ="To go"&CHAR(10)&"(FY − YTD)" -> To go (FY − YTD) | M6: ="Δ geselect."&CHAR(10)&"vs Budget" -> Δ geselect. vs Budget | N6: ="Δ geselect."&CHAR(10)&"vs "&IF(Sel_Prev="","vorige",Sel_Prev) -> Δ geselect. vs Q2 | O6: Vorige versie (hulp) | P6: Definitie / bron
B7: Omzet opstal | C7: =IF(ISNUMBER(CALC_Versies!$G$5),CALC_Versies!$G$5/P_Factor,CALC_Versies!$G$5) -> 113431.26 | D7: =IF(ISNUMBER(CALC_Versies!$G$6),CALC_Versies!$G$6/P_Factor,CALC_Versies!$G$6) -> 111433.4 | E7: =IF(ISNUMBER(CALC_Versies!$G$7),CALC_Versies!$G$7/P_Factor,CALC_Versies!$G$7) -> 106938.2 | F7: =IF(ISNUMBER(CALC_Versies!$G$8),CALC_Versies!$G$8/P_Factor,CALC_Versies!$G$8) -> 108436.6 | G7: =IF(ISNUMBER(CALC_Versies!$G$9),CALC_Versies!$G$9/P_Factor,CALC_Versies!$G$9) -> n.b. | H7: =IF(ISNUMBER(CALC_Versies!$G$10),CALC_Versies!$G$10/P_Factor,CALC_Versies!$G$10) -> 108436.6 | J7: =IF(ISNUMBER(CALC_Versies!$G$11),CALC_Versies!$G$11/P_Factor,CALC_Versies!$G$11) -> 108436.6 | K7: =IF(ISNUMBER(CALC_Versies!$K$11),CALC_Versies!$K$11/P_Factor,CALC_Versies!$K$11) -> 70483.79 | L7: =IF(K7="n.v.t.",J7,IF(AND(ISNUMBER(J7),ISNUMBER(K7)),J7-K7,"n.b.")) -> 37952.81 | M7: =IF(AND(ISNUMBER(J7),ISNUMBER(C7)),J7-C7,"n.b.") -> -4994.66 | N7: =IF(AND(ISNUMBER(J7),ISNUMBER(O7)),J7-O7,"n.b.") -> 1498.398 | O7: =IF(ISNUMBER(CALC_Versies!$G$12),CALC_Versies!$G$12/P_Factor,CALC_Versies!$G$12) -> 106938.2 | P7: ZPMW03, Type=Opstal (Mapping). FY RJ = −Bedrijfsopbrengsten LJ − OP.BOB RJ; RJ+1 = −OP.BOB RJ+1
B8: Omzet deelnemingen | C8: =IF(ISNUMBER(CALC_Versies!$H$5),CALC_Versies!$H$5/P_Factor,CALC_Versies!$H$5) -> 5094.18 | D8: =IF(ISNUMBER(CALC_Versies!$H$6),CALC_Versies!$H$6/P_Factor,CALC_Versies!$H$6) -> 5320.588 | E8: =IF(ISNUMBER(CALC_Versies!$H$7),CALC_Versies!$H$7/P_Factor,CALC_Versies!$H$7) -> 5830.006 | F8: =IF(ISNUMBER(CALC_Versies!$H$8),CALC_Versies!$H$8/P_Factor,CALC_Versies!$H$8) -> 5660.2 | G8: =IF(ISNUMBER(CALC_Versies!$H$9),CALC_Versies!$H$9/P_Factor,CALC_Versies!$H$9) -> n.b. | H8: =IF(ISNUMBER(CALC_Versies!$H$10),CALC_Versies!$H$10/P_Factor,CALC_Versies!$H$10) -> 5660.2 | J8: =IF(ISNUMBER(CALC_Versies!$H$11),CALC_Versies!$H$11/P_Factor,CALC_Versies!$H$11) -> 5660.2 | K8: =IF(ISNUMBER(CALC_Versies!$L$11),CALC_Versies!$L$11/P_Factor,CALC_Versies!$L$11) -> 3679.13 | L8: =IF(K8="n.v.t.",J8,IF(AND(ISNUMBER(J8),ISNUMBER(K8)),J8-K8,"n.b.")) -> 1981.07 | M8: =IF(AND(ISNUMBER(J8),ISNUMBER(C8)),J8-C8,"n.b.") -> 566.02 | N8: =IF(AND(ISNUMBER(J8),ISNUMBER(O8)),J8-O8,"n.b.") -> -169.806 | O8: =IF(ISNUMBER(CALC_Versies!$H$12),CALC_Versies!$H$12/P_Factor,CALC_Versies!$H$12) -> 5830.006 | P8: ZPMW03, Type=Deelneming (Mapping). Al op aandeelbasis; geen aandeel toegepast
B9: Taakstelling omzet | C9: =IF(ISNUMBER(CALC_Versies!$Y$5),CALC_Versies!$Y$5/P_Factor,CALC_Versies!$Y$5) -> n.b. | D9: =IF(ISNUMBER(CALC_Versies!$Y$6),CALC_Versies!$Y$6/P_Factor,CALC_Versies!$Y$6) -> n.b. | E9: =IF(ISNUMBER(CALC_Versies!$Y$7),CALC_Versies!$Y$7/P_Factor,CALC_Versies!$Y$7) -> n.b. | F9: =IF(ISNUMBER(CALC_Versies!$Y$8),CALC_Versies!$Y$8/P_Factor,CALC_Versies!$Y$8) -> n.b. | G9: =IF(ISNUMBER(CALC_Versies!$Y$9),CALC_Versies!$Y$9/P_Factor,CALC_Versies!$Y$9) -> n.b. | H9: =IF(ISNUMBER(CALC_Versies!$Y$10),CALC_Versies!$Y$10/P_Factor,CALC_Versies!$Y$10) -> n.b. | J9: =IF(ISNUMBER(CALC_Versies!$Y$11),CALC_Versies!$Y$11/P_Factor,CALC_Versies!$Y$11) -> n.b. | K9: =IF(ISNUMBER(CALC_Versies!$AF$11),CALC_Versies!$AF$11/P_Factor,CALC_Versies!$AF$11) -> n.b. | L9: ="" | M9: =IF(AND(ISNUMBER(J9),ISNUMBER(C9)),J9-C9,"n.b.") -> n.b. | N9: =IF(AND(ISNUMBER(J9),ISNUMBER(O9)),J9-O9,"n.b.") -> n.b. | O9: =IF(ISNUMBER(CALC_Versies!$Y$12),CALC_Versies!$Y$12/P_Factor,CALC_Versies!$Y$12) -> n.b. | P9: Invoer_Aanvullend (rubriek Taakstelling omzet)
B10: Interne eliminaties | C10: =IF(ISNUMBER(CALC_Versies!$Z$5),CALC_Versies!$Z$5/P_Factor,CALC_Versies!$Z$5) -> n.b. | D10: =IF(ISNUMBER(CALC_Versies!$Z$6),CALC_Versies!$Z$6/P_Factor,CALC_Versies!$Z$6) -> n.b. | E10: =IF(ISNUMBER(CALC_Versies!$Z$7),CALC_Versies!$Z$7/P_Factor,CALC_Versies!$Z$7) -> n.b. | F10: =IF(ISNUMBER(CALC_Versies!$Z$8),CALC_Versies!$Z$8/P_Factor,CALC_Versies!$Z$8) -> n.b. | G10: =IF(ISNUMBER(CALC_Versies!$Z$9),CALC_Versies!$Z$9/P_Factor,CALC_Versies!$Z$9) -> n.b. | H10: =IF(ISNUMBER(CALC_Versies!$Z$10),CALC_Versies!$Z$10/P_Factor,CALC_Versies!$Z$10) -> n.b. | J10: =IF(ISNUMBER(CALC_Versies!$Z$11),CALC_Versies!$Z$11/P_Factor,CALC_Versies!$Z$11) -> n.b. | K10: =IF(ISNUMBER(CALC_Versies!$AG$11),CALC_Versies!$AG$11/P_Factor,CALC_Versies!$AG$11) -> n.b. | L10: ="" | M10: =IF(AND(ISNUMBER(J10),ISNUMBER(C10)),J10-C10,"n.b.") -> n.b. | N10: =IF(AND(ISNUMBER(J10),ISNUMBER(O10)),J10-O10,"n.b.") -> n.b. | O10: =IF(ISNUMBER(CALC_Versies!$Z$12),CALC_Versies!$Z$12/P_Factor,CALC_Versies!$Z$12) -> n.b. | P10: Invoer_Aanvullend
B11: Omzet old | C11: =IF(ISNUMBER(C7),SUM(C7,C8,C9,C10),C7) -> 118525.44 | D11: =IF(ISNUMBER(D7),SUM(D7,D8,D9,D10),D7) -> 116753.98 | E11: =IF(ISNUMBER(E7),SUM(E7,E8,E9,E10),E7) -> 112768.21 | F11: =IF(ISNUMBER(F7),SUM(F7,F8,F9,F10),F7) -> 114096.8 | G11: =IF(ISNUMBER(G7),SUM(G7,G8,G9,G10),G7) -> n.b. | H11: =IF(ISNUMBER(H7),SUM(H7,H8,H9,H10),H7) -> 114096.8 | J11: =IF(ISNUMBER(J7),SUM(J7,J8,J9,J10),J7) -> 114096.8 | K11: =IF(ISNUMBER(K7),SUM(K7,K8,K9,K10),K7) -> 74162.92 | L11: =IF(K11="n.v.t.",J11,IF(AND(ISNUMBER(J11),ISNUMBER(K11)),J11-K11,"n.b.")) -> 39933.88 | M11: =IF(AND(ISNUMBER(J11),ISNUMBER(C11)),J11-C11,"n.b.") -> -4428.64 | N11: =IF(AND(ISNUMBER(J11),ISNUMBER(O11)),J11-O11,"n.b.") -> 1328.592 | O11: =IF(ISNUMBER(O7),SUM(O7,O8,O9,O10),O7) -> 112768.21 | P11: Subtotaal: opstal + deelnemingen + taakstelling + interne eliminaties
B12: IFRS-eliminaties | C12: =IF(ISNUMBER(CALC_Versies!$AA$5),CALC_Versies!$AA$5/P_Factor,CALC_Versies!$AA$5) -> n.b. | D12: =IF(ISNUMBER(CALC_Versies!$AA$6),CALC_Versies!$AA$6/P_Factor,CALC_Versies!$AA$6) -> n.b. | E12: =IF(ISNUMBER(CALC_Versies!$AA$7),CALC_Versies!$AA$7/P_Factor,CALC_Versies!$AA$7) -> n.b. | F12: =IF(ISNUMBER(CALC_Versies!$AA$8),CALC_Versies!$AA$8/P_Factor,CALC_Versies!$AA$8) -> n.b. | G12: =IF(ISNUMBER(CALC_Versies!$AA$9),CALC_Versies!$AA$9/P_Factor,CALC_Versies!$AA$9) -> n.b. | H12: =IF(ISNUMBER(CALC_Versies!$AA$10),CALC_Versies!$AA$10/P_Factor,CALC_Versies!$AA$10) -> n.b. | J12: =IF(ISNUMBER(CALC_Versies!$AA$11),CALC_Versies!$AA$11/P_Factor,CALC_Versies!$AA$11) -> n.b. | K12: =IF(ISNUMBER(CALC_Versies!$AH$11),CALC_Versies!$AH$11/P_Factor,CALC_Versies!$AH$11) -> n.b. | L12: ="" | M12: =IF(AND(ISNUMBER(J12),ISNUMBER(C12)),J12-C12,"n.b.") -> n.b. | N12: =IF(AND(ISNUMBER(J12),ISNUMBER(O12)),J12-O12,"n.b.") -> n.b. | O12: =IF(ISNUMBER(CALC_Versies!$AA$12),CALC_Versies!$AA$12/P_Factor,CALC_Versies!$AA$12) -> n.b. | P12: Invoer_Aanvullend. IFRS J/N wordt NIET automatisch geëlimineerd (zie memo)
B13: Omzet IFRS | C13: =IF(ISNUMBER(C11),SUM(C11,C12),C11) -> 118525.44 | D13: =IF(ISNUMBER(D11),SUM(D11,D12),D11) -> 116753.98 | E13: =IF(ISNUMBER(E11),SUM(E11,E12),E11) -> 112768.21 | F13: =IF(ISNUMBER(F11),SUM(F11,F12),F11) -> 114096.8 | G13: =IF(ISNUMBER(G11),SUM(G11,G12),G11) -> n.b. | H13: =IF(ISNUMBER(H11),SUM(H11,H12),H11) -> 114096.8 | J13: =IF(ISNUMBER(J11),SUM(J11,J12),J11) -> 114096.8 | K13: =IF(ISNUMBER(K11),SUM(K11,K12),K11) -> 74162.92 | L13: =IF(K13="n.v.t.",J13,IF(AND(ISNUMBER(J13),ISNUMBER(K13)),J13-K13,"n.b.")) -> 39933.88 | M13: =IF(AND(ISNUMBER(J13),ISNUMBER(C13)),J13-C13,"n.b.") -> -4428.64 | N13: =IF(AND(ISNUMBER(J13),ISNUMBER(O13)),J13-O13,"n.b.") -> 1328.592 | O13: =IF(ISNUMBER(O11),SUM(O11,O12),O11) -> 112768.21 | P13: Omzet old + IFRS-eliminaties
B15: Projectresultaat (BOR) opstal | C15: =IF(ISNUMBER(CALC_Versies!$I$5),CALC_Versies!$I$5/P_Factor,CALC_Versies!$I$5) -> 10424.156 | D15: =IF(ISNUMBER(CALC_Versies!$I$6),CALC_Versies!$I$6/P_Factor,CALC_Versies!$I$6) -> 10291.72 | E15: =IF(ISNUMBER(CALC_Versies!$I$7),CALC_Versies!$I$7/P_Factor,CALC_Versies!$I$7) -> 9993.7389 | F15: =IF(ISNUMBER(CALC_Versies!$I$8),CALC_Versies!$I$8/P_Factor,CALC_Versies!$I$8) -> 10093.066 | G15: =IF(ISNUMBER(CALC_Versies!$I$9),CALC_Versies!$I$9/P_Factor,CALC_Versies!$I$9) -> n.b. | H15: =IF(ISNUMBER(CALC_Versies!$I$10),CALC_Versies!$I$10/P_Factor,CALC_Versies!$I$10) -> 10093.066 | J15: =IF(ISNUMBER(CALC_Versies!$I$11),CALC_Versies!$I$11/P_Factor,CALC_Versies!$I$11) -> 10093.066 | K15: =IF(ISNUMBER(CALC_Versies!$M$11),CALC_Versies!$M$11/P_Factor,CALC_Versies!$M$11) -> 6560.4929 | L15: =IF(K15="n.v.t.",J15,IF(AND(ISNUMBER(J15),ISNUMBER(K15)),J15-K15,"n.b.")) -> 3532.5731 | M15: =IF(AND(ISNUMBER(J15),ISNUMBER(C15)),J15-C15,"n.b.") -> -331.0902 | N15: =IF(AND(ISNUMBER(J15),ISNUMBER(O15)),J15-O15,"n.b.") -> 99.32706 | O15: =IF(ISNUMBER(CALC_Versies!$I$12),CALC_Versies!$I$12/P_Factor,CALC_Versies!$I$12) -> 9993.7389 | P15: ZPMW03: FY RJ = −Bruto (omzet) result. LJ − OP.BOR RJ. Verlies blijft negatief (geen ABS)
B16: Projectresultaat (BOR) deelnemingen | C16: =IF(ISNUMBER(CALC_Versies!$J$5),CALC_Versies!$J$5/P_Factor,CALC_Versies!$J$5) -> 345.7188 | D16: =IF(ISNUMBER(CALC_Versies!$J$6),CALC_Versies!$J$6/P_Factor,CALC_Versies!$J$6) -> 361.08408 | E16: =IF(ISNUMBER(CALC_Versies!$J$7),CALC_Versies!$J$7/P_Factor,CALC_Versies!$J$7) -> 395.65596 | F16: =IF(ISNUMBER(CALC_Versies!$J$8),CALC_Versies!$J$8/P_Factor,CALC_Versies!$J$8) -> 384.132 | G16: =IF(ISNUMBER(CALC_Versies!$J$9),CALC_Versies!$J$9/P_Factor,CALC_Versies!$J$9) -> n.b. | H16: =IF(ISNUMBER(CALC_Versies!$J$10),CALC_Versies!$J$10/P_Factor,CALC_Versies!$J$10) -> 384.132 | J16: =IF(ISNUMBER(CALC_Versies!$J$11),CALC_Versies!$J$11/P_Factor,CALC_Versies!$J$11) -> 384.132 | K16: =IF(ISNUMBER(CALC_Versies!$N$11),CALC_Versies!$N$11/P_Factor,CALC_Versies!$N$11) -> 249.6858 | L16: =IF(K16="n.v.t.",J16,IF(AND(ISNUMBER(J16),ISNUMBER(K16)),J16-K16,"n.b.")) -> 134.4462 | M16: =IF(AND(ISNUMBER(J16),ISNUMBER(C16)),J16-C16,"n.b.") -> 38.4132 | N16: =IF(AND(ISNUMBER(J16),ISNUMBER(O16)),J16-O16,"n.b.") -> -11.52396 | O16: =IF(ISNUMBER(CALC_Versies!$J$12),CALC_Versies!$J$12/P_Factor,CALC_Versies!$J$12) -> 395.65596 | P16: Idem, Type=Deelneming
B17: Projectresultaten / BOR | C17: =IF(ISNUMBER(C15),SUM(C15,C16),C15) -> 10769.875 | D17: =IF(ISNUMBER(D15),SUM(D15,D16),D15) -> 10652.804 | E17: =IF(ISNUMBER(E15),SUM(E15,E16),E15) -> 10389.395 | F17: =IF(ISNUMBER(F15),SUM(F15,F16),F15) -> 10477.198 | G17: =IF(ISNUMBER(G15),SUM(G15,G16),G15) -> n.b. | H17: =IF(ISNUMBER(H15),SUM(H15,H16),H15) -> 10477.198 | J17: =IF(ISNUMBER(J15),SUM(J15,J16),J15) -> 10477.198 | K17: =IF(ISNUMBER(K15),SUM(K15,K16),K15) -> 6810.1787 | L17: =IF(K17="n.v.t.",J17,IF(AND(ISNUMBER(J17),ISNUMBER(K17)),J17-K17,"n.b.")) -> 3667.0193 | M17: =IF(AND(ISNUMBER(J17),ISNUMBER(C17)),J17-C17,"n.b.") -> -292.677 | N17: =IF(AND(ISNUMBER(J17),ISNUMBER(O17)),J17-O17,"n.b.") -> 87.8031 | O17: =IF(ISNUMBER(O15),SUM(O15,O16),O15) -> 10389.395 | P17: Subtotaal BOR
B18: AK-dekking | C18: =IF(ISNUMBER(CALC_Versies!$AB$5),CALC_Versies!$AB$5/P_Factor,CALC_Versies!$AB$5) -> n.b. | D18: =IF(ISNUMBER(CALC_Versies!$AB$6),CALC_Versies!$AB$6/P_Factor,CALC_Versies!$AB$6) -> n.b. | E18: =IF(ISNUMBER(CALC_Versies!$AB$7),CALC_Versies!$AB$7/P_Factor,CALC_Versies!$AB$7) -> n.b. | F18: =IF(ISNUMBER(CALC_Versies!$AB$8),CALC_Versies!$AB$8/P_Factor,CALC_Versies!$AB$8) -> n.b. | G18: =IF(ISNUMBER(CALC_Versies!$AB$9),CALC_Versies!$AB$9/P_Factor,CALC_Versies!$AB$9) -> n.b. | H18: =IF(ISNUMBER(CALC_Versies!$AB$10),CALC_Versies!$AB$10/P_Factor,CALC_Versies!$AB$10) -> n.b. | J18: =IF(ISNUMBER(CALC_Versies!$AB$11),CALC_Versies!$AB$11/P_Factor,CALC_Versies!$AB$11) -> n.b. | K18: =IF(ISNUMBER(CALC_Versies!$AI$11),CALC_Versies!$AI$11/P_Factor,CALC_Versies!$AI$11) -> n.b. | L18: ="" | M18: =IF(AND(ISNUMBER(J18),ISNUMBER(C18)),J18-C18,"n.b.") -> n.b. | N18: =IF(AND(ISNUMBER(J18),ISNUMBER(O18)),J18-O18,"n.b.") -> n.b. | O18: =IF(ISNUMBER(CALC_Versies!$AB$12),CALC_Versies!$AB$12/P_Factor,CALC_Versies!$AB$12) -> n.b. | P18: Invoer_Aanvullend. Geen generiek AK-percentage toegepast
B19: Fees | C19: =IF(ISNUMBER(CALC_Versies!$AC$5),CALC_Versies!$AC$5/P_Factor,CALC_Versies!$AC$5) -> n.b. | D19: =IF(ISNUMBER(CALC_Versies!$AC$6),CALC_Versies!$AC$6/P_Factor,CALC_Versies!$AC$6) -> n.b. | E19: =IF(ISNUMBER(CALC_Versies!$AC$7),CALC_Versies!$AC$7/P_Factor,CALC_Versies!$AC$7) -> n.b. | F19: =IF(ISNUMBER(CALC_Versies!$AC$8),CALC_Versies!$AC$8/P_Factor,CALC_Versies!$AC$8) -> n.b. | G19: =IF(ISNUMBER(CALC_Versies!$AC$9),CALC_Versies!$AC$9/P_Factor,CALC_Versies!$AC$9) -> n.b. | H19: =IF(ISNUMBER(CALC_Versies!$AC$10),CALC_Versies!$AC$10/P_Factor,CALC_Versies!$AC$10) -> n.b. | J19: =IF(ISNUMBER(CALC_Versies!$AC$11),CALC_Versies!$AC$11/P_Factor,CALC_Versies!$AC$11) -> n.b. | K19: =IF(ISNUMBER(CALC_Versies!$AJ$11),CALC_Versies!$AJ$11/P_Factor,CALC_Versies!$AJ$11) -> n.b. | L19: ="" | M19: =IF(AND(ISNUMBER(J19),ISNUMBER(C19)),J19-C19,"n.b.") -> n.b. | N19: =IF(AND(ISNUMBER(J19),ISNUMBER(O19)),J19-O19,"n.b.") -> n.b. | O19: =IF(ISNUMBER(CALC_Versies!$AC$12),CALC_Versies!$AC$12/P_Factor,CALC_Versies!$AC$12) -> n.b. | P19: Invoer_Aanvullend
B20: Overige resultaten | C20: =IF(ISNUMBER(CALC_Versies!$AD$5),CALC_Versies!$AD$5/P_Factor,CALC_Versies!$AD$5) -> n.b. | D20: =IF(ISNUMBER(CALC_Versies!$AD$6),CALC_Versies!$AD$6/P_Factor,CALC_Versies!$AD$6) -> n.b. | E20: =IF(ISNUMBER(CALC_Versies!$AD$7),CALC_Versies!$AD$7/P_Factor,CALC_Versies!$AD$7) -> n.b. | F20: =IF(ISNUMBER(CALC_Versies!$AD$8),CALC_Versies!$AD$8/P_Factor,CALC_Versies!$AD$8) -> n.b. | G20: =IF(ISNUMBER(CALC_Versies!$AD$9),CALC_Versies!$AD$9/P_Factor,CALC_Versies!$AD$9) -> n.b. | H20: =IF(ISNUMBER(CALC_Versies!$AD$10),CALC_Versies!$AD$10/P_Factor,CALC_Versies!$AD$10) -> n.b. | J20: =IF(ISNUMBER(CALC_Versies!$AD$11),CALC_Versies!$AD$11/P_Factor,CALC_Versies!$AD$11) -> n.b. | K20: =IF(ISNUMBER(CALC_Versies!$AK$11),CALC_Versies!$AK$11/P_Factor,CALC_Versies!$AK$11) -> n.b. | L20: ="" | M20: =IF(AND(ISNUMBER(J20),ISNUMBER(C20)),J20-C20,"n.b.") -> n.b. | N20: =IF(AND(ISNUMBER(J20),ISNUMBER(O20)),J20-O20,"n.b.") -> n.b. | O20: =IF(ISNUMBER(CALC_Versies!$AD$12),CALC_Versies!$AD$12/P_Factor,CALC_Versies!$AD$12) -> n.b. | P20: Invoer_Aanvullend
B21: Taakstelling EBIT | C21: =IF(ISNUMBER(CALC_Versies!$AE$5),CALC_Versies!$AE$5/P_Factor,CALC_Versies!$AE$5) -> n.b. | D21: =IF(ISNUMBER(CALC_Versies!$AE$6),CALC_Versies!$AE$6/P_Factor,CALC_Versies!$AE$6) -> n.b. | E21: =IF(ISNUMBER(CALC_Versies!$AE$7),CALC_Versies!$AE$7/P_Factor,CALC_Versies!$AE$7) -> n.b. | F21: =IF(ISNUMBER(CALC_Versies!$AE$8),CALC_Versies!$AE$8/P_Factor,CALC_Versies!$AE$8) -> n.b. | G21: =IF(ISNUMBER(CALC_Versies!$AE$9),CALC_Versies!$AE$9/P_Factor,CALC_Versies!$AE$9) -> n.b. | H21: =IF(ISNUMBER(CALC_Versies!$AE$10),CALC_Versies!$AE$10/P_Factor,CALC_Versies!$AE$10) -> n.b. | J21: =IF(ISNUMBER(CALC_Versies!$AE$11),CALC_Versies!$AE$11/P_Factor,CALC_Versies!$AE$11) -> n.b. | K21: =IF(ISNUMBER(CALC_Versies!$AL$11),CALC_Versies!$AL$11/P_Factor,CALC_Versies!$AL$11) -> n.b. | L21: ="" | M21: =IF(AND(ISNUMBER(J21),ISNUMBER(C21)),J21-C21,"n.b.") -> n.b. | N21: =IF(AND(ISNUMBER(J21),ISNUMBER(O21)),J21-O21,"n.b.") -> n.b. | O21: =IF(ISNUMBER(CALC_Versies!$AE$12),CALC_Versies!$AE$12/P_Factor,CALC_Versies!$AE$12) -> n.b. | P21: Invoer_Aanvullend
B22: EBIT-bijdrage | C22: =IF(ISNUMBER(C17),SUM(C17,C18,C19,C20,C21),C17) -> 10769.875 | D22: =IF(ISNUMBER(D17),SUM(D17,D18,D19,D20,D21),D17) -> 10652.804 | E22: =IF(ISNUMBER(E17),SUM(E17,E18,E19,E20,E21),E17) -> 10389.395 | F22: =IF(ISNUMBER(F17),SUM(F17,F18,F19,F20,F21),F17) -> 10477.198 | G22: =IF(ISNUMBER(G17),SUM(G17,G18,G19,G20,G21),G17) -> n.b. | H22: =IF(ISNUMBER(H17),SUM(H17,H18,H19,H20,H21),H17) -> 10477.198 | J22: =IF(ISNUMBER(J17),SUM(J17,J18,J19,J20,J21),J17) -> 10477.198 | K22: =IF(ISNUMBER(K17),SUM(K17,K18,K19,K20,K21),K17) -> 6810.1787 | L22: =IF(K22="n.v.t.",J22,IF(AND(ISNUMBER(J22),ISNUMBER(K22)),J22-K22,"n.b.")) -> 3667.0193 | M22: =IF(AND(ISNUMBER(J22),ISNUMBER(C22)),J22-C22,"n.b.") -> -292.677 | N22: =IF(AND(ISNUMBER(J22),ISNUMBER(O22)),J22-O22,"n.b.") -> 87.8031 | O22: =IF(ISNUMBER(O17),SUM(O17,O18,O19,O20,O21),O17) -> 10389.395 | P22: BOR + AK-dekking + fees + overige resultaten + taakstelling EBIT
B24: BOR % | C24: =IF(AND(ISNUMBER(C17),ISNUMBER(C28)),IF(C28<>0,C17/C28,"n.b."),"n.b.") -> 0.090865514 | D24: =IF(AND(ISNUMBER(D17),ISNUMBER(D28)),IF(D28<>0,D17/D28,"n.b."),"n.b.") -> 0.091241462 | E24: =IF(AND(ISNUMBER(E17),ISNUMBER(E28)),IF(E28<>0,E17/E28,"n.b."),"n.b.") -> 0.092130531 | F24: =IF(AND(ISNUMBER(F17),ISNUMBER(F28)),IF(F28<>0,F17/F28,"n.b."),"n.b.") -> 0.091827273 | G24: =IF(AND(ISNUMBER(G17),ISNUMBER(G28)),IF(G28<>0,G17/G28,"n.b."),"n.b.") -> n.b. | H24: =IF(AND(ISNUMBER(H17),ISNUMBER(H28)),IF(H28<>0,H17/H28,"n.b."),"n.b.") -> 0.091827273 | J24: =IF(AND(ISNUMBER(J17),ISNUMBER(J28)),IF(J28<>0,J17/J28,"n.b."),"n.b.") -> 0.091827273 | K24: =IF(AND(ISNUMBER(K17),ISNUMBER(K28)),IF(K28<>0,K17/K28,"n.b."),"n.b.") -> 0.091827273 | L24: ="" | M24: =IF(AND(ISNUMBER(J24),ISNUMBER(C24)),J24-C24,"n.b.") -> 0.00096175922 | N24: =IF(AND(ISNUMBER(J24),ISNUMBER(O24)),J24-O24,"n.b.") -> -0.00030325817 | O24: =IF(AND(ISNUMBER(O17),ISNUMBER(O28)),IF(O28<>0,O17/O28,"n.b."),"n.b.") -> 0.092130531 | P24: Totale BOR / totale projectomzet (opstal + deelnemingen). Geen gemiddelde van projectpercentages
B25: EBIT % | C25: =IF(AND(ISNUMBER(C22),ISNUMBER(C11)),IF(C11<>0,C22/C11,"n.b."),"n.b.") -> 0.090865514 | D25: =IF(AND(ISNUMBER(D22),ISNUMBER(D11)),IF(D11<>0,D22/D11,"n.b."),"n.b.") -> 0.091241462 | E25: =IF(AND(ISNUMBER(E22),ISNUMBER(E11)),IF(E11<>0,E22/E11,"n.b."),"n.b.") -> 0.092130531 | F25: =IF(AND(ISNUMBER(F22),ISNUMBER(F11)),IF(F11<>0,F22/F11,"n.b."),"n.b.") -> 0.091827273 | G25: =IF(AND(ISNUMBER(G22),ISNUMBER(G11)),IF(G11<>0,G22/G11,"n.b."),"n.b.") -> n.b. | H25: =IF(AND(ISNUMBER(H22),ISNUMBER(H11)),IF(H11<>0,H22/H11,"n.b."),"n.b.") -> 0.091827273 | J25: =IF(AND(ISNUMBER(J22),ISNUMBER(J11)),IF(J11<>0,J22/J11,"n.b."),"n.b.") -> 0.091827273 | K25: =IF(AND(ISNUMBER(K22),ISNUMBER(K11)),IF(K11<>0,K22/K11,"n.b."),"n.b.") -> 0.091827273 | L25: ="" | M25: =IF(AND(ISNUMBER(J25),ISNUMBER(C25)),J25-C25,"n.b.") -> 0.00096175922 | N25: =IF(AND(ISNUMBER(J25),ISNUMBER(O25)),J25-O25,"n.b.") -> -0.00030325817 | O25: =IF(AND(ISNUMBER(O22),ISNUMBER(O11)),IF(O11<>0,O22/O11,"n.b."),"n.b.") -> 0.092130531 | P25: EBIT-bijdrage / Omzet old (definitie te bevestigen, zie Productievragen)
B27: Memo
B28: Omzet projecten (noemer BOR %) | C28: =IF(ISNUMBER(C7),SUM(C7,C8),C7) -> 118525.44 | D28: =IF(ISNUMBER(D7),SUM(D7,D8),D7) -> 116753.98 | E28: =IF(ISNUMBER(E7),SUM(E7,E8),E7) -> 112768.21 | F28: =IF(ISNUMBER(F7),SUM(F7,F8),F7) -> 114096.8 | G28: =IF(ISNUMBER(G7),SUM(G7,G8),G7) -> n.b. | H28: =IF(ISNUMBER(H7),SUM(H7,H8),H7) -> 114096.8 | J28: =IF(ISNUMBER(J7),SUM(J7,J8),J7) -> 114096.8 | K28: =IF(ISNUMBER(K7),SUM(K7,K8),K7) -> 74162.92 | L28: =IF(K28="n.v.t.",J28,IF(AND(ISNUMBER(J28),ISNUMBER(K28)),J28-K28,"n.b.")) -> 39933.88 | M28: =IF(AND(ISNUMBER(J28),ISNUMBER(C28)),J28-C28,"n.b.") -> -4428.64 | N28: =IF(AND(ISNUMBER(J28),ISNUMBER(O28)),J28-O28,"n.b.") -> 1328.592 | O28: =IF(ISNUMBER(O7),SUM(O7,O8),O7) -> 112768.21 | P28: Omzet opstal + deelnemingen
B29: waarvan projecten met IFRS = N | C29: =IF(ISNUMBER(CALC_Versies!$O$5),CALC_Versies!$O$5/P_Factor,CALC_Versies!$O$5) -> 5094.18 | D29: =IF(ISNUMBER(CALC_Versies!$O$6),CALC_Versies!$O$6/P_Factor,CALC_Versies!$O$6) -> 5320.588 | E29: =IF(ISNUMBER(CALC_Versies!$O$7),CALC_Versies!$O$7/P_Factor,CALC_Versies!$O$7) -> 5830.006 | F29: =IF(ISNUMBER(CALC_Versies!$O$8),CALC_Versies!$O$8/P_Factor,CALC_Versies!$O$8) -> 5660.2 | G29: =IF(ISNUMBER(CALC_Versies!$O$9),CALC_Versies!$O$9/P_Factor,CALC_Versies!$O$9) -> n.b. | H29: =IF(ISNUMBER(CALC_Versies!$O$10),CALC_Versies!$O$10/P_Factor,CALC_Versies!$O$10) -> 5660.2 | J29: =IF(ISNUMBER(CALC_Versies!$O$11),CALC_Versies!$O$11/P_Factor,CALC_Versies!$O$11) -> 5660.2 | K29: ="" | L29: ="" | M29: =IF(AND(ISNUMBER(J29),ISNUMBER(C29)),J29-C29,"n.b.") -> 566.02 | N29: =IF(AND(ISNUMBER(J29),ISNUMBER(O29)),J29-O29,"n.b.") -> -169.806 | O29: =IF(ISNUMBER(CALC_Versies!$O$12),CALC_Versies!$O$12/P_Factor,CALC_Versies!$O$12) -> 5830.006 | P29: Informatief: IFRS J/N is een dimensie, geen automatische eliminatie- of consolidatieregel
B30: BOR projecten met IFRS = N | C30: =IF(ISNUMBER(CALC_Versies!$P$5),CALC_Versies!$P$5/P_Factor,CALC_Versies!$P$5) -> 345.7188 | D30: =IF(ISNUMBER(CALC_Versies!$P$6),CALC_Versies!$P$6/P_Factor,CALC_Versies!$P$6) -> 361.08408 | E30: =IF(ISNUMBER(CALC_Versies!$P$7),CALC_Versies!$P$7/P_Factor,CALC_Versies!$P$7) -> 395.65596 | F30: =IF(ISNUMBER(CALC_Versies!$P$8),CALC_Versies!$P$8/P_Factor,CALC_Versies!$P$8) -> 384.132 | G30: =IF(ISNUMBER(CALC_Versies!$P$9),CALC_Versies!$P$9/P_Factor,CALC_Versies!$P$9) -> n.b. | H30: =IF(ISNUMBER(CALC_Versies!$P$10),CALC_Versies!$P$10/P_Factor,CALC_Versies!$P$10) -> 384.132 | J30: =IF(ISNUMBER(CALC_Versies!$P$11),CALC_Versies!$P$11/P_Factor,CALC_Versies!$P$11) -> 384.132 | K30: ="" | L30: ="" | M30: =IF(AND(ISNUMBER(J30),ISNUMBER(C30)),J30-C30,"n.b.") -> 38.4132 | N30: =IF(AND(ISNUMBER(J30),ISNUMBER(O30)),J30-O30,"n.b.") -> -11.52396 | O30: =IF(ISNUMBER(CALC_Versies!$P$12),CALC_Versies!$P$12/P_Factor,CALC_Versies!$P$12) -> 395.65596 | P30: Informatief
B31: Woningverkopen (aantal, aandeelbasis) | C31: =CALC_Versies!$Q$5 -> 372 | D31: =CALC_Versies!$Q$6 -> 366 | E31: =CALC_Versies!$Q$7 -> 355 | F31: =CALC_Versies!$Q$8 -> 360 | G31: =CALC_Versies!$Q$9 -> n.b. | H31: =CALC_Versies!$Q$10 -> 360 | J31: =CALC_Versies!$Q$11 -> 360 | K31: =CALC_Versies!$R$11 -> 193 | L31: ="" | M31: =IF(AND(ISNUMBER(J31),ISNUMBER(C31)),J31-C31,"n.b.") -> -12 | N31: =IF(AND(ISNUMBER(J31),ISNUMBER(O31)),J31-O31,"n.b.") -> 5 | O31: =CALC_Versies!$Q$12 -> 355 | P31: Woningetalage 'Huidig jaar' (RJ) / 'Volgend jaar' (RJ+1). Verkopen ≠ opleveringen/transporten
B33: Leeswijzer
B34: • Budget/Q1–Q4 = vastgelegde (onveranderlijke) FY-jaarprognoses uit Vastlegging. Een nieuwe upload wijzigt deze kolommen niet. ● = versie bevat een correctie (revisie > 0).
B35: • 'Upload … concept' = live berekend uit SRC_ZPMW03/SRC_Woningetalage; wordt pas een versie na handmatige vastlegging (tab Vastleggen).
B36: • 'Realisatie YTD' (groen, cursief) is géén prognose: actual t/m de peildatum van de geselecteerde versie. To go = geselecteerde FY − realisatie van dezelfde peildatum.
B37: • n.b. = niet beschikbaar (geen vastgelegde of aanvullende invoer) — nooit stil als nul. n.v.t. = doeljaar ligt na het versiejaar, dus nog geen realisatie.
B38: • Oranje subtotaal = onvolledig: minstens één onderliggende post is n.b. De som bevat alleen de beschikbare posten.
B39: • Tekens: omzet en resultaat positief, verlies negatief (rood). Aanvullende invoer in managementteken (+ verhoogt omzet/resultaat).

Sheet Projecten
B1: ="Projectoverzicht "&P_Regio&" — omzet doeljaar "&Sel_Doeljaar&" ("&P_Eenheid&")" -> Projectoverzicht Demo Regio — omzet doeljaar 2026 (EUR x 1.000)
B2: ="Geselecteerde versie: "&Sel_Label&" · realisatie en to go van dezelfde peildatum · filter met de pijltjes in rij 9" -> Geselecteerde versie: Q3 2026 (vastgesteld) · realisatie en to go van dezelfde peildatum · filter met de pijltjes in rij 9
B6: Totaal (zichtbare regels) | E6: =IF(SUBTOTAL(102,E10:E109)=0,"n.b.",SUBTOTAL(109,E10:E109)) -> 118525.44 | F6: =IF(SUBTOTAL(102,F10:F109)=0,"n.b.",SUBTOTAL(109,F10:F109)) -> 116753.98 | G6: =IF(SUBTOTAL(102,G10:G109)=0,"n.b.",SUBTOTAL(109,G10:G109)) -> 112768.21 | H6: =IF(SUBTOTAL(102,H10:H109)=0,"n.b.",SUBTOTAL(109,H10:H109)) -> 114096.8 | I6: =IF(SUBTOTAL(102,I10:I109)=0,"n.b.",SUBTOTAL(109,I10:I109)) -> n.b. | J6: =IF(SUBTOTAL(102,J10:J109)=0,"n.b.",SUBTOTAL(109,J10:J109)) -> 114096.8 | K6: =IF(SUBTOTAL(102,K10:K109)=0,"n.b.",SUBTOTAL(109,K10:K109)) -> 114096.8 | L6: =IF(SUBTOTAL(102,L10:L109)=0,"n.b.",SUBTOTAL(109,L10:L109)) -> 74162.92 | ... N6: =IF(SUBTOTAL(102,N10:N109)=0,"n.b.",SUBTOTAL(109,N10:N109)) -> 10477.198 | O6: =IF(AND(ISNUMBER(N6),ISNUMBER(K6)),IF(K6<>0,N6/K6,"n.b."),"n.b.") -> 0.091827273 | P6: =IF(SUBTOTAL(102,P10:P109)=0,"n.b.",SUBTOTAL(109,P10:P109)) -> -4428.64 | Q6: =IF(SUBTOTAL(102,Q10:Q109)=0,"n.b.",SUBTOTAL(109,Q10:Q109)) -> 1328.592 | R6: =COUNTIF(R10:R109,"Verlies")&" verliesproject(en)" -> 2 verliesproject(en)
B7: Marge % totaal = som BOR / som omzet (geen gemiddelde). Realisatie en to go horen bij de peildatum van de geselecteerde versie.
E8: Budget | F8: Q1 | G8: Q2 | H8: Q3 | I8: Q4
A9: WBS-element | B9: Projectnaam | C9: Type | D9: IFRS | E9: ="Budget"&CHAR(10)&"FY "&Sel_Doeljaar -> Budget FY 2026 | F9: ="Q1 "&P_VJ&CHAR(10)&"FY" -> Q1 2026 FY | G9: ="Q2 "&P_VJ&CHAR(10)&"FY" -> Q2 2026 FY | H9: ="Q3 "&P_VJ&CHAR(10)&"FY" -> Q3 2026 FY | I9: ="Q4 "&P_VJ&CHAR(10)&"FY" -> Q4 2026 FY | J9: ="Upload"&CHAR(10)&"concept" -> Upload concept | K9: ="Geselect."&CHAR(10)&Sel_Versie&" FY" -> Geselect. Q3 FY | L9: Realisatie YTD | M9: Omzet to go | N9: ="BOR FY"&CHAR(10)&Sel_Versie -> BOR FY Q3 | O9: Marge % | P9: Δ vs Budget | Q9: ="Δ vs "&IF(Sel_Prev="","vorige",Sel_Prev) -> Δ vs Q2 | R9: Verlies | S9: Toelichting (Invoer_Toelichting)
A10: =IF(VERW_Project!$A6="","",VERW_Project!$A6) -> G.900001.8.9090 | B10: =IF($A10="","",VERW_Project!$C6) -> Lindehaven, Parkzoom fase 1 | C10: =IF($A10="","",VERW_Project!$D6) -> Opstal | D10: =IF($A10="","",VERW_Project!$I6) -> J | E10: =IF($A10="","",IF(ISNUMBER(IF(COUNTIFS(L_Actief,1,L_WBS,$A10,L_Doeljaar,Sel_Doeljaar,L_Versiejaar,P_VJ,L_Versie,E$8,L_Kengetal,"Omzet FY")=0,"n.b.",SUMIFS(L_Waarde,L_Actief,1,L_WBS,$A10,L_Doeljaar,Sel_Doeljaar,L_Versiejaar,P_VJ,L_Versie,E$8,L_Kengetal,"Omzet FY"))),IF(COUNTIFS(L_Actief,1,L_WBS,$A10,L_Doeljaar,Sel_Doeljaar,L_Versiejaar,P_VJ,L_Versie,E$8,L_Kengetal,"Omzet FY")=0,"n.b.",SUMIFS(L_Waarde,L_Actief,1,L_WBS,$A10,L_Doeljaar,Sel_Doeljaar,L_Versiejaar,P_VJ,L_Versie,E$8,L_Kengetal,"Omzet FY"))/P_Factor,IF(COUNTIFS(L_Actief,1,L_WBS,$A10,L_Doeljaar,Sel_Doeljaar,L_Versiejaar,P_VJ,L_Versie,E$8,L_Kengetal,"Omzet FY")=0,"n.b.",SUMIFS(L_Waarde,L_Actief,1,L_WBS,$A10,L_Doeljaar,Sel_Doeljaar,L_Versiejaar,P_VJ,L_Versie,E$8,L_Kengetal,"Omzet FY")))) -> 6152.96 | F10: =IF($A10="","",IF(ISNUMBER(IF(COUNTIFS(L_Actief,1,L_WBS,$A10,L_Doeljaar,Sel_Doeljaar,L_Versiejaar,P_VJ,L_Versie,F$8,L_Kengetal,"Omzet FY")=0,"n.b.",SUMIFS(L_Waarde,L_Actief,1,L_WBS,$A10,L_Doeljaar,Sel_Doeljaar,L_Versiejaar,P_VJ,L_Versie,F$8,L_Kengetal,"Omzet FY"))),IF(COUNTIFS(L_Actief,1,L_WBS,$A10,L_Doeljaar,Sel_Doeljaar,L_Versiejaar,P_VJ,L_Versie,F$8,L_Kengetal,"Omzet FY")=0,"n.b.",SUMIFS(L_Waarde,L_Actief,1,L_WBS,$A10,L_Doeljaar,Sel_Doeljaar,L_Versiejaar,P_VJ,L_Versie,F$8,L_Kengetal,"Omzet FY"))/P_Factor,IF(COUNTIFS(L_Actief,1,L_WBS,$A10,L_Doeljaar,Sel_Doeljaar,L_Versiejaar,P_VJ,L_Versie,F$8,L_Kengetal,"Omzet FY")=0,"n.b.",SUMIFS(L_Waarde,L_Actief,1,L_WBS,$A10,L_Doeljaar,Sel_Doeljaar,L_Versiejaar,P_VJ,L_Versie,F$8,L_Kengetal,"Omzet FY")))) -> 5929.216 | G10: =IF($A10="","",IF(ISNUMBER(IF(COUNTIFS(L_Actief,1,L_WBS,$A10,L_Doeljaar,Sel_Doeljaar,L_Versiejaar,P_VJ,L_Versie,G$8,L_Kengetal,"Omzet FY")=0,"n.b.",SUMIFS(L_Waarde,L_Actief,1,L_WBS,$A10,L_Doeljaar,Sel_Doeljaar,L_Versiejaar,P_VJ,L_Versie,G$8,L_Kengetal,"Omzet FY"))),IF(COUNTIFS(L_Actief,1,L_WBS,$A10,L_Doeljaar,Sel_Doeljaar,L_Versiejaar,P_VJ,L_Versie,G$8,L_Kengetal,"Omzet FY")=0,"n.b.",SUMIFS(L_Waarde,L_Actief,1,L_WBS,$A10,L_Doeljaar,Sel_Doeljaar,L_Versiejaar,P_VJ,L_Versie,G$8,L_Kengetal,"Omzet FY"))/P_Factor,IF(COUNTIFS(L_Actief,1,L_WBS,$A10,L_Doeljaar,Sel_Doeljaar,L_Versiejaar,P_VJ,L_Versie,G$8,L_Kengetal,"Omzet FY")=0,"n.b.",SUMIFS(L_Waarde,L_Actief,1,L_WBS,$A10,L_Doeljaar,Sel_Doeljaar,L_Versiejaar,P_VJ,L_Versie,G$8,L_Kengetal,"Omzet FY")))) -> 5425.792 | H10: =IF($A10="","",IF(ISNUMBER(IF(COUNTIFS(L_Actief,1,L_WBS,$A10,L_Doeljaar,Sel_Doeljaar,L_Versiejaar,P_VJ,L_Versie,H$8,L_Kengetal,"Omzet FY")=0,"n.b.",SUMIFS(L_Waarde,L_Actief,1,L_WBS,$A10,L_Doeljaar,Sel_Doeljaar,L_Versiejaar,P_VJ,L_Versie,H$8,L_Kengetal,"Omzet FY"))),IF(COUNTIFS(L_Actief,1,L_WBS,$A10,L_Doeljaar,Sel_Doeljaar,L_Versiejaar,P_VJ,L_Versie,H$8,L_Kengetal,"Omzet FY")=0,"n.b.",SUMIFS(L_Waarde,L_Actief,1,L_WBS,$A10,L_Doeljaar,Sel_Doeljaar,L_Versiejaar,P_VJ,L_Versie,H$8,L_Kengetal,"Omzet FY"))/P_Factor,IF(COUNTIFS(L_Actief,1,L_WBS,$A10,L_Doeljaar,Sel_Doeljaar,L_Versiejaar,P_VJ,L_Versie,H$8,L_Kengetal,"Omzet FY")=0,"n.b.",SUMIFS(L_Waarde,L_Actief,1,L_WBS,$A10,L_Doeljaar,Sel_Doeljaar,L_Versiejaar,P_VJ,L_Versie,H$8,L_Kengetal,"Omzet FY")))) -> 5593.6 | I10: =IF($A10="","",IF(ISNUMBER(IF(COUNTIFS(L_Actief,1,L_WBS,$A10,L_Doeljaar,Sel_Doeljaar,L_Versiejaar,P_VJ,L_Versie,I$8,L_Kengetal,"Omzet FY")=0,"n.b.",SUMIFS(L_Waarde,L_Actief,1,L_WBS,$A10,L_Doeljaar,Sel_Doeljaar,L_Versiejaar,P_VJ,L_Versie,I$8,L_Kengetal,"Omzet FY"))),IF(COUNTIFS(L_Actief,1,L_WBS,$A10,L_Doeljaar,Sel_Doeljaar,L_Versiejaar,P_VJ,L_Versie,I$8,L_Kengetal,"Omzet FY")=0,"n.b.",SUMIFS(L_Waarde,L_Actief,1,L_WBS,$A10,L_Doeljaar,Sel_Doeljaar,L_Versiejaar,P_VJ,L_Versie,I$8,L_Kengetal,"Omzet FY"))/P_Factor,IF(COUNTIFS(L_Actief,1,L_WBS,$A10,L_Doeljaar,Sel_Doeljaar,L_Versiejaar,P_VJ,L_Versie,I$8,L_Kengetal,"Omzet FY")=0,"n.b.",SUMIFS(L_Waarde,L_Actief,1,L_WBS,$A10,L_Doeljaar,Sel_Doeljaar,L_Versiejaar,P_VJ,L_Versie,I$8,L_Kengetal,"Omzet FY")))) -> n.b. | J10: =IF($A10="","",IF(ISNUMBER(IF(Sel_Doeljaar=P_RJ,VERW_Project!$P6,IF(Sel_Doeljaar=P_RJ+1,VERW_Project!$R6,"n.b."))),IF(Sel_Doeljaar=P_RJ,VERW_Project!$P6,IF(Sel_Doeljaar=P_RJ+1,VERW_Project!$R6,"n.b."))/P_Factor,IF(Sel_Doeljaar=P_RJ,VERW_Project!$P6,IF(Sel_Doeljaar=P_RJ+1,VERW_Project!$R6,"n.b.")))) -> 5593.6 | K10: =IF($A10="","",IF(Sel_Bron="Vastgesteld",INDEX($E10:$I10,MATCH(Sel_Versie,$E$8:$I$8,0)),IF(Sel_Bron="Concept",J10,"n.b."))) -> 5593.6 | L10: =IF($A10="","",IF(Sel_Doeljaar>P_VJ,"n.v.t.",IF(Sel_Bron="Vastgesteld",IF(ISNUMBER(IF(COUNTIFS(L_Actief,1,L_WBS,$A10,L_Doeljaar,Sel_Doeljaar,L_Versiejaar,P_VJ,L_Versie,Sel_Versie,L_Kengetal,"Omzet actual YTD")=0,"n.b.",SUMIFS(L_Waarde,L_Actief,1,L_WBS,$A10,L_Doeljaar,Sel_Doeljaar,L_Versiejaar,P_VJ,L_Versie,Sel_Versie,L_Kengetal,"Omzet actual YTD"))),IF(COUNTIFS(L_Actief,1,L_WBS,$A10,L_Doeljaar,Sel_Doeljaar,L_Versiejaar,P_VJ,L_Versie,Sel_Versie,L_Kengetal,"Omzet actual YTD")=0,"n.b.",SUMIFS(L_Waarde,L_Actief,1,L_WBS,$A10,L_Doeljaar,Sel_Doeljaar,L_Versiejaar,P_VJ,L_Versie,Sel_Versie,L_Kengetal,"Omzet actual YTD"))/P_Factor,IF(COUNTIFS(L_Actief,1,L_WBS,$A10,L_Doeljaar,Sel_Doeljaar,L_Versiejaar,P_VJ,L_Versie,Sel_Versie,L_Kengetal,"Omzet actual YTD")=0,"n.b.",SUMIFS(L_Waarde,L_Actief,1,L_WBS,$A10,L_Doeljaar,Sel_Doeljaar,L_Versiejaar,P_VJ,L_Versie,Sel_Versie,L_Kengetal,"Omzet actual YTD"))),IF(Sel_Bron="Concept",IF(ISNUMBER(IF(Sel_Doeljaar=P_RJ,VERW_Project!$L6,"n.v.t.")),IF(Sel_Doeljaar=P_RJ,VERW_Project!$L6,"n.v.t.")/P_Factor,IF(Sel_Doeljaar=P_RJ,VERW_Project!$L6,"n.v.t.")),"n.b.")))) -> 3635.84 | M10: =IF($A10="","",IF(L10="n.v.t.",K10,IF(AND(ISNUMBER(K10),ISNUMBER(L10)),K10-L10,"n.b."))) -> 1957.76 | N10: =IF($A10="","",IF(Sel_Bron="Vastgesteld",IF(ISNUMBER(IF(COUNTIFS(L_Actief,1,L_WBS,$A10,L_Doeljaar,Sel_Doeljaar,L_Versiejaar,P_VJ,L_Versie,Sel_Versie,L_Kengetal,"BOR FY")=0,"n.b.",SUMIFS(L_Waarde,L_Actief,1,L_WBS,$A10,L_Doeljaar,Sel_Doeljaar,L_Versiejaar,P_VJ,L_Versie,Sel_Versie,L_Kengetal,"BOR FY"))),IF(COUNTIFS(L_Actief,1,L_WBS,$A10,L_Doeljaar,Sel_Doeljaar,L_Versiejaar,P_VJ,L_Versie,Sel_Versie,L_Kengetal,"BOR FY")=0,"n.b.",SUMIFS(L_Waarde,L_Actief,1,L_WBS,$A10,L_Doeljaar,Sel_Doeljaar,L_Versiejaar,P_VJ,L_Versie,Sel_Versie,L_Kengetal,"BOR FY"))/P_Factor,IF(COUNTIFS(L_Actief,1,L_WBS,$A10,L_Doeljaar,Sel_Doeljaar,L_Versiejaar,P_VJ,L_Versie,Sel_Versie,L_Kengetal,"BOR FY")=0,"n.b.",SUMIFS(L_Waarde,L_Actief,1,L_WBS,$A10,L_Doeljaar,Sel_Doeljaar,L_Versiejaar,P_VJ,L_Versie,Sel_Versie,L_Kengetal,"BOR FY"))),IF(Sel_Bron="Concept",IF(ISNUMBER(IF(Sel_Doeljaar=P_RJ,VERW_Project!$Q6,IF(Sel_Doeljaar=P_RJ+1,VERW_Project!$S6,"n.b."))),IF(Sel_Doeljaar=P_RJ,VERW_Project!$Q6,IF(Sel_Doeljaar=P_RJ+1,VERW_Project!$S6,"n.b."))/P_Factor,IF(Sel_Doeljaar=P_RJ,VERW_Project!$Q6,IF(Sel_Doeljaar=P_RJ+1,VERW_Project!$S6,"n.b."))),"n.b."))) -> 503.424 | O10: =IF($A10="","",IF(AND(ISNUMBER(N10),ISNUMBER(K10)),IF(K10<>0,N10/K10,"n.b."),"n.b.")) -> 0.09 | P10: =IF($A10="","",IF(AND(ISNUMBER(K10),ISNUMBER(E10)),K10-E10,"n.b.")) -> -559.36 | Q10: =IF($A10="","",IF(AND(ISNUMBER(K10),ISNUMBER(W10)),K10-W10,"n.b.")) -> 167.808 | R10: =IF($A10="","",IF(ISNUMBER(N10),IF(N10<0,"Verlies",""),"")) | S10: =IF($A10="","",IFERROR(INDEX(T_Txt,MATCH($A10&"|"&Sel_Doeljaar&"|"&P_VJ&"|"&Sel_Versie,T_Key,0)),"")) | U10: =IF(AND(AND($A10<>"",OR(Sel_Type="Alle",$C10=Sel_Type),OR(Sel_Project="Alle",$B10=Sel_Project)),ISNUMBER(K10)),K10+ROW()/1000000000,"") -> 5593.6 | V10: =IF(AND(AND($A10<>"",OR(Sel_Type="Alle",$C10=Sel_Type),OR(Sel_Project="Alle",$B10=Sel_Project)),ISNUMBER(Q10)),ABS(Q10)+ROW()/1000000000,"") -> 167.808 | W10: =IF(OR($A10="",Sel_Prev=""),"n.b.",IF(ISNUMBER(IF(COUNTIFS(L_Actief,1,L_WBS,$A10,L_Doeljaar,Sel_Doeljaar,L_Versiejaar,P_VJ,L_Versie,Sel_Prev,L_Kengetal,"Omzet FY")=0,"n.b.",SUMIFS(L_Waarde,L_Actief,1,L_WBS,$A10,L_Doeljaar,Sel_Doeljaar,L_Versiejaar,P_VJ,L_Versie,Sel_Prev,L_Kengetal,"Omzet FY"))),IF(COUNTIFS(L_Actief,1,L_WBS,$A10,L_Doeljaar,Sel_Doeljaar,L_Versiejaar,P_VJ,L_Versie,Sel_Prev,L_Kengetal,"Omzet FY")=0,"n.b.",SUMIFS(L_Waarde,L_Actief,1,L_WBS,$A10,L_Doeljaar,Sel_Doeljaar,L_Versiejaar,P_VJ,L_Versie,Sel_Prev,L_Kengetal,"Omzet FY"))/P_Factor,IF(COUNTIFS(L_Actief,1,L_WBS,$A10,L_Doeljaar,Sel_Doeljaar,L_Versiejaar,P_VJ,L_Versie,Sel_Prev,L_Kengetal,"Omzet FY")=0,"n.b.",SUMIFS(L_Waarde,L_Actief,1,L_WBS,$A10,L_Doeljaar,Sel_Doeljaar,L_Versiejaar,P_VJ,L_Versie,Sel_Prev,L_Kengetal,"Omzet FY")))) -> 5425.792
